{"trial_id": "2", "hyperparameters": {"space": [{"class_name": "Choice", "config": {"name": "optimizer", "default": "adam", "conditions": [], "values": ["adam", "sgd", "rmsprop", "adadelta"], "ordered": false}}], "values": {"optimizer": "sgd"}}, "metrics": {"metrics": {"loss": {"direction": "min", "observations": [{"value": [0.43187135457992554], "step": 9}]}, "accuracy": {"direction": "max", "observations": [{"value": [0.818965494632721], "step": 9}]}, "val_loss": {"direction": "min", "observations": [{"value": [0.4698004126548767], "step": 9}]}, "val_accuracy": {"direction": "max", "observations": [{"value": [0.7974137663841248], "step": 9}]}}}, "score": 0.7974137663841248, "best_step": 9, "status": "COMPLETED", "message": "Traceback (most recent call last):\n  File \"C:\\Users\\MANISHARMA\\AppData\\Local\\Programs\\Python\\Python310\\lib\\site-packages\\keras_tuner\\src\\engine\\base_tuner.py\", line 273, in _try_run_and_update_trial\n    self._run_and_update_trial(trial, *fit_args, **fit_kwargs)\n  File \"C:\\Users\\MANISHARMA\\AppData\\Local\\Programs\\Python\\Python310\\lib\\site-packages\\keras_tuner\\src\\engine\\base_tuner.py\", line 238, in _run_and_update_trial\n    results = self.run_trial(trial, *fit_args, **fit_kwargs)\n  File \"C:\\Users\\MANISHARMA\\AppData\\Local\\Programs\\Python\\Python310\\lib\\site-packages\\keras_tuner\\src\\engine\\tuner.py\", line 314, in run_trial\n    obj_value = self._build_and_fit_model(trial, *args, **copied_kwargs)\n  File \"C:\\Users\\MANISHARMA\\AppData\\Local\\Programs\\Python\\Python310\\lib\\site-packages\\keras_tuner\\src\\engine\\tuner.py\", line 233, in _build_and_fit_model\n    results = self.hypermodel.fit(hp, model, *args, **kwargs)\n  File \"C:\\Users\\MANISHARMA\\AppData\\Local\\Programs\\Python\\Python310\\lib\\site-packages\\keras_tuner\\src\\engine\\hypermodel.py\", line 149, in fit\n    return model.fit(*args, **kwargs)\n  File \"C:\\Users\\MANISHARMA\\AppData\\Local\\Programs\\Python\\Python310\\lib\\site-packages\\keras\\utils\\traceback_utils.py\", line 70, in error_handler\n    raise e.with_traceback(filtered_tb) from None\n  File \"C:\\Users\\MANISHARMA\\AppData\\Local\\Programs\\Python\\Python310\\lib\\site-packages\\tensorflow\\python\\framework\\constant_op.py\", line 103, in convert_to_eager_tensor\n    return ops.EagerTensor(value, ctx.device_name, dtype)\nValueError: Failed to convert a NumPy array to a Tensor (Unsupported object type int).\n"}